Workbook

Sheet Read me first 
B1: CSCF Assessment template instructions - Mandatory controls - Version 2025
B2: PURPOSE
B3: This template is provided for convenience; SWIFT recommends that independent assessors, involved in the assessment of the Customer Security Controls Framework (CSCF) controls implementation for a SWIFT user, use it to document the assessment results. This workbook provides guidelines that apply only the CSCF v2025 mandatory controls; a separate file is available for assessing CSCF advisory controls. The changes in comparison with v2024 are highlighted in bold.
B4: INSTRUCTIONS
B5: 1 | C5: Important note: User data contained within this assessment workbook is considered sensitive and must not be disclosed to any party without express written consent from the SWIFT user.
B6: 2 | C6: Assessors should use a risk based approach to assess the user’s compliance with the CSP control; i.e. assess the security goal, regardless of the implementation method used (be it the suggested guidelines or alternatives). As such, to comply with a CSP security control, users must implement a solution that: (i) Meets the stated control objective, (ii) Addresses the risks and (iii) Covers the documented in-scope components relevant for the user’s architecture. The control statement is a suggested means to fulfil the control objective and the implementation guidelines are common methods for implementing the control. Even if guidelines can be a good way to start an assessment, the implementation guidance section of each control in the CSCF should never be considered as an "audit checklist" as each user’s implementation may vary. Therefore, in the case that some implementation guidelines elements are not present or partially covered, mitigations as well as particular environment specificities have to be taken into account to properly assess the overall compliance adherence level (again, as per the suggested guidelines or as per alternatives).
B7: 3 | C7: SWIFT highly recommends that users also include the CSCF advisory controls in the independent assessment; some of the advisory may be turned mandatory in the next version of the CSCF
B8: 4 | C8: Begin the assessment process by thoroughly reviewing the Customer Security Controls Framework (CSCF), assessment templates, and all other SWIFT-provided assessment guidance. Access to documentation through your swift.com user account (your company being registered with SWIFT), or documentation to be provided by the SWIFT user if your company is not registered and you do not have an a swift.Com user account.
C9: Access the Attestation Support page
B10: 5 | C10: Reference the “User Data” tab and populate all applicable cells with the information requested. Note that all individual assessors involved in executing the end-to-end assessment process should be included in the “Assessor Name(s)” field. Additionally, names provided in the “Assessor Name(s)” field should be accompanied by the applicable professional certification(s) held by each individual assessor.
B11: 6 | C11: Depending on the architecture type of the community member in question, complete the following coloured tabs that represent the control data contained within the CSCF. • Architecture A1 and A2 : BLUE + GREEN + RED + YELLOW tabs • Architecture A3: BLUE + GREEN + RED tabs • Architecture A4: BLUE + GREEN tabs • Architecture B: BLUE tabs
B12: 7 | C12: For each applicable tab defined above, review the control objective, in-scope components, risk drivers, control statement, and control context. Assessors should reference the full text of the CSCF document for a full listing of all control and guideline-level details. This guidance applies to the internal or external assessors to assess the existing/implemented controls and their suitability/effectiveness.
B13: 8 | C13: The assessment templates directly correlate to the CSCF and highlight which CSCF controls are applicable to the user’s architecture type. For each applicable control, the relevant template sets out the control objective, any underpinning key principle(s) and SWIFT’s guidance with respect to their implementation. By use of the template, the assessor can then confirm whether those that are applicable to the user are complied with, either via SWIFT’s implementation guidance or, for typically large or complex institutions, via an alternative implementation method. (Specifically, for CSCF control 1.1, the key principle 1.1.C2 may not be applicable). Finally, some CSCF controls although relevant for the user’s SWIFT architecture type may, in rare cases, not be applicable depending upon the user’s specific local infrastructure. In such cases, they should be assessed as 'Not Applicable'. An example of this would be Control 6.2 (Anti-Virus) which, whilst likely to be applicable in most environments would is not likely to be applicable in a Linux environment. - please refer to the KYC-SA baseline for the identification of such controls.
B14: 9 | C14: For each Implementation Guideline in the "Assessments Results" section, indicate whether or not the user has fulfilled the guideline statement using the appropriate drop-down list(s) available at the right side of the worksheet. Note that the only available responses are “yes”, “no”, and “N/A”. Responses marked “N/A” are not detrimental to the overall disposition of any control.
B15: 10 | C15: Support the above-mentioned finding by populating the corresponding cell(s) marked "<Observations & response justification - address all subordinate implementation details as documented in the CSCF>" for each guideline. As noted, assessors should address all subordinate details documented for each Implementation Guideline as provided in the CSCF.
B16: 11 | C16: For each guideline in the "Assessments Results" section, indicate whether or not the user has used an alternative implementation means to fill the control requirement(s) of said guideline. Use the appropriate drop-down list(s) available at the right side of the worksheet. Note that the use of alternative implementation means is not detrimental to the overall conclusion of the control.
B17: 12 | C17: For any control where alternative implementation means were used to fill the control requirement(s), provide a full explanation of the alternative means utilised in the corresponding cells marked "<Alternative guideline implementation approach and details>". Note that the worksheet will grey out these cells for any guidelines that have been addressed using the standard implementation method. Responses provided should be comprehensive and detail how all applicable risks are addressed by the user's custom implementation.
B18: 13 | C18: When the above steps have been completed, the worksheet will automatically mark the control as either "In Place" or "Not in Place" depending on the input provided by the assessor in the "Assessments Results" section. Do not attempt to manually alter any fields that are automatically populated (non-modifiable cells are password protected).
B19: 14 | C19: The workbook will automatically display a summary of the dispositions of all controls in the "Summary" tab.
B20: 15 | C20: When the assessment is complete, assessors should print the completion letter provided in the "Completion Letter" WORD document posted in the same ZIP file as this Excel Sheet, as described in the Independent Assessment Framework (chapter "7.1 Assessment Report and Completion Letter"). Then manually sign the letter, and provide it to the user for whom the assessment was performed.
B21: 16 | C21: When the assessment is complete, assessors must provided the Swift user with an assessment report as described in the Independent Assessment Framework (chapter "7.1 Assessment Report and Completion Letter"). A CSP assessment report template is available on the Swift Knowledge Center.
B22: 17 | C22: Note in case of reliance on conclusion of previous assessment cycle, controls's conclusion that have been relied on previous assessment should be marked as such in the <Observations & response justification> boxes of those controls.(as described in the Independent Assessment Framework, chapter "3.4 Reliance on the Previous Assessment’s Conclusions")

Sheet Revision Record
A1: Date | B1: Change
A2: 43861 | B2: Removed Completion letter tab to make it a standalone word document
A3: 43861 | B3: Inserted a revision record sheet
A4: 43861 | B4: Inserted a clause on each control, before the Implementation guidelines to stress on the risk based approach to be used by assessors
A5: 44029 | B5: Alignment with v2021
A6: 44165 | B6: correction in tab colouring, and A4 inclusion and references to the completion letter
A7: 44257 | B7: Correct 1.1. remove section on internet access - now moved to 1.4
A8: 44312 | B8: Correct summary sheet to deselect 2.1 for A4
A9: 44476 | B9: updated for the CSCF v2022
A10: 44525 | B10: Corrected formulas to show 'Not Applicable' in the sheet Summary for controls that are not applicable for architecture A4
A11: 44609 | B11: Updated the in scope architectures for CTRL 2.10. A4 and B were incorrectly included in the scope.
A12: 44774 | B12: Update with v2023
A13: 45145 | B13: Update with v2024
A14: 45495 | B14: Update with v2025

Sheet User Data
A1: USER BACKGROUND DATA SHEET
A2: Customer Name | B2: ABC Bank UK
A3: BIC
A4: Architecture Type | B4: A4
A5: Assessment Start Date
A6: Assessment End Date
A7: CSCF Version | B7: 2025
A8: Assessor Firm
A9: Lead Assessor Name
A10: Lead Assessor Title
A11: Assessor Name(s)

Sheet Summary
A1: MANDATORY CONTROLS SUMMARY
A2: Control Objective | B2: Title | C2: Architecture Applicability | H2: Implementation Means | I2: Control Disposition
C3: A1 | D3: A2 | E3: A3 | F3: A4 | G3: B
A4: 1.1 | B4: SWIFT Environment Protection | C4: X | D4: X | E4: X | H4: =IF(OR('1.1'!D22="",'1.1'!D26="",'1.1'!D30="",'1.1'!D34="",'1.1'!D38="",'1.1'!D42=""),"TBD",IF(OR('1.1'!D22="Yes",'1.1'!D26="Yes",'1.1'!D30="Yes",'1.1'!D34="Yes",'1.1'!D38="Yes",'1.1'!D42="Yes"),"Alternative","Standard")) -> TBD | I4: ='1.1'!D45 -> Not Applicable
A5: 1.2 | B5: Operating System Privileged Account Control | C5: X | D5: X | E5: X | F5: X | G5: A | H5: =IF('1.2'!D22="","TBD",IF('1.2'!D22="Yes","Alternative","Standard")) -> Standard | I5: ='1.2'!D25 -> In Place
A6: 1.3 | B6: Virtualisation or Cloud Platform Protection | C6: X | D6: X | E6: X | F6: X | G6: A | H6: =IF('1.3'!D25="","TBD",IF('1.3'!D25="Yes","Alternative","Standard")) -> Standard | I6: ='1.3'!D28 -> In Place
A7: 1.4 | B7: Restriction of Internet Access | C7: X | D7: X | E7: X | F7: X | G7: X | H7: =IF('1.4'!D23="","TBD",IF('1.4'!D23="Yes","Alternative","Standard")) -> Standard | I7: ='1.4'!D26 -> In Place
A8: 1.5 | B8: Customer Environment Protection | F8: X | H8: =IF(OR('1.5'!D18="",'1.5'!D22="",'1.5'!D26="",'1.5'!D30="",'1.5'!D34="",'1.5'!D38=""),"TBD",IF(OR('1.5'!D18="Yes",'1.5'!D22="Yes",'1.5'!D26="Yes",'1.5'!D30="Yes",'1.5'!D34="Yes",'1.5'!D38="Yes"),"Alternative","Standard")) -> Standard | I8: ='1.5'!D41 -> In Place
A9: 2.1 | B9: Internal Data Flow Security | C9: X | D9: X | E9: X | H9: =IF('2.1'!D17="","TBD",IF('2.1'!D17="Yes","Alternative","Standard")) -> TBD | I9: ='2.1'!D20 -> Not Applicable
A10: 2.2 | B10: Security Updates | C10: X | D10: X | E10: X | F10: X | G10: X | H10: =IF('2.2'!D21="","TBD",IF('2.2'!D21="Yes","Alternative","Standard")) -> Standard | I10: ='2.2'!D24 -> In Place
A11: 2.3 | B11: System Hardening | C11: X | D11: X | E11: X | F11: X | G11: X | H11: =IF('2.3'!D19="","TBD",IF('2.3'!D19="Yes","Alternative","Standard")) -> Standard | I11: ='2.3'!D22 -> In Place
A12: 2.6 | B12: Operator Session Confidentiality and Integrity | C12: X | D12: X | E12: X | F12: X | G12: X | H12: =IF('2.6'!D25="","TBD",IF('2.6'!D25="Yes","Alternative","Standard")) -> Standard | I12: ='2.6'!D28 -> In Place
A13: 2.7 | B13: Vulnerability Scanning | C13: X | D13: X | E13: X | F13: X | G13: A | H13: =IF('2.7'!D19="","TBD",IF('2.7'!D19="Yes","Alternative","Standard")) -> Standard | I13: ='2.7'!D22 -> In Place
A14: 2.8 | B14: Outsourced Critical Activity Protection | C14: X | D14: X | E14: X | F14: X | G14: X | H14: =IF('2.8'!D16="","TBD",IF('2.8'!D16="Yes","Alternative","Standard")) -> Standard | I14: ='2.8'!D19 -> In Place
A15: 2.9 | B15: Transaction Business Controls | C15: X | D15: X | E15: X | F15: X | G15: X | H15: =IF('2.9'!D14="","TBD",IF('2.9'!D14="Yes","Alternative","Standard")) -> Standard | I15: ='2.9'!D17 -> In Place
A16: 2.10 | B16: Application Hardening | C16: X | D16: X | E16: X | H16: =IF('2.10'!D17="","TBD",IF('2.10'!D17="Yes","Alternative","Standard")) -> TBD | I16: ='2.10'!D20 -> Not Applicable
A17: 3.1 | B17: Physical Security | C17: X | D17: X | E17: X | F17: X | G17: X | H17: =IF('3.1'!D20="","TBD",IF('3.1'!D20="Yes","Alternative","Standard")) -> Standard | I17: ='3.1'!D23 -> In Place
A18: 4.1 | B18: Password Policy | C18: X | D18: X | E18: X | F18: X | G18: X | H18: =IF('4.1'!D22="","TBD",IF('4.1'!D22="Yes","Alternative","Standard")) -> Standard | I18: ='4.1'!D25 -> In Place
A19: 4.2 | B19: Multi-Factor Authentication | C19: X | D19: X | E19: X | F19: X | G19: X | H19: =IF('4.2'!D18="","TBD",IF('4.2'!D18="Yes","Alternative","Standard")) -> Standard | I19: ='4.2'!D21 -> In Place
A20: 5.1 | B20: Logical Access Control | C20: X | D20: X | E20: X | F20: X | G20: X | H20: =IF('5.1'!D23="","TBD",IF('5.1'!D23="Yes","Alternative","Standard")) -> Standard | I20: ='5.1'!D26 -> In Place
A21: 5.2 | B21: Token Management | C21: X | D21: X | E21: X | F21: X | G21: X | H21: =IF('5.2'!D16="","TBD",IF('5.2'!D16="Yes","Alternative","Standard")) -> Standard | I21: ='5.2'!D19 -> In Place
A22: 5.4 | B22: Physical and Logical Password Storage Protection | C22: X | D22: X | E22: X | F22: X | G22: X | H22: =IF('5.4'!D23="","TBD",IF('5.4'!D23="Yes","Alternative","Standard")) -> Standard | I22: ='5.4'!D26 -> In Place
A23: 6.1 | B23: Malware Protection | C23: X | D23: X | E23: X | F23: X | G23: X | H23: =IF('6.1'!D19="","TBD",IF('6.1'!D19="Yes","Alternative","Standard")) -> Standard | I23: ='6.1'!D22 -> In Place
A24: 6.2 | B24: Software Integrity | C24: X | D24: X | E24: X | F24: A | H24: =IF('6.2'!D20="","TBD",IF('6.2'!D20="Yes","Alternative","Standard")) -> TBD
A25: 6.3 | B25: Database Integrity | C25: X | D25: X | F25: A | H25: =IF('6.3'!D13="","TBD",IF('6.3'!D13="Yes","Alternative","Standard")) -> TBD
A26: 6.4 | B26: Logging and Monitoring | C26: X | D26: X | E26: X | F26: X | G26: X | H26: =IF('6.4'!D23="","TBD",IF('6.4'!D23="Yes","Alternative","Standard")) -> Standard | I26: ='6.4'!D26 -> In Place
A27: 7.1 | B27: Cyber Incident Response Planning | C27: X | D27: X | E27: X | F27: X | G27: X | H27: =IF('7.1'!D13="","TBD",IF('7.1'!D13="Yes","Alternative","Standard")) -> Standard | I27: ='7.1'!D16 -> In Place
A28: 7.2 | B28: Security Training and Awareness | C28: X | D28: X | E28: X | F28: X | G28: X | H28: =IF('7.2'!D13="","TBD",IF('7.2'!D13="Yes","Alternative","Standard")) -> Standard | I28: ='7.2'!D16 -> In Place
H30: * Important note : In KYC-SA application, a compliant control (whatever by means of alternative implementation or using the Swift implementation guidelines) will be declared as "I comply as per Control definition"

Sheet 1.1
A1: 1.1 | B1: Swift ENVIRONMENT PROTECTION
A2: CONTROL INFORMATION
A3: CONTROL OBJECTIVE Ensure the protection of the user's Swift infrastructure from potentially compromised elements of the general IT environment and external environment.
A4: IN-SCOPE COMPONENTS | C4: RISK DRIVERS
A5: • Messaging interface | C5: • Compromise of enterprise authentication system
A6: • Communication interface | C6: • Compromise of user credentials
A7: • GUI | C7: • Credential replay
A8: • SwiftNet Link | C8: • Exposure to internet-based attacks
A9: • Hardware Security Module (HSM) | C9: • Unauthorized access
A10: • Swift or customer connector
A11: • [Advisory: customer client connector]
A12: • Jump server
A13: • Dedicated and general-purpose operator PCs
A14: CONTROL STATEMENT A separated secure zone safeguards the user's Swift infrastructure from compromises and attacks on the broader enterprise and external environments.
A15: CONTROL CONTEXT Segmentation between the user's Swift infrastructure and its larger enterprise network reduces the attack surface and has shown to be an effective way to defend against cyber attacks that commonly involve compromise of the general enterprise IT environment. Effective segmentation will include network-level separation, access restrictions, and connectivity restrictions.
A16: ASSESSMENT RESULTS
A17: Implementation Guideline-Level Detail
A18: Assessors should use a risk based approach to assess the user’s compliance with the CSP control; i.e. assess the security goal, regardless of the implementation method used (be it the suggested guidelines or alternatives). As such, to comply with a CSP security control, users must implement a solution that: (i)Meets the stated control objective, (ii) Addresses the risks and (iii) Covers the documented in-scope components relevant for the user’s architecture. The control statement is a suggested mean to fulfil the control objective and the implementation guidelines are common methods for implementing the control. Even if guidelines can be a good way to start an assessment, the implementation guidance section should never be considered as an "audit checklist" as each user’s implementation may vary. Therefore, in the case that some implementation guidelines elements are not present or partially covered, mitigations as well as particular environment specificities have to be taken into account to properly assess the overall compliance adherence level (again, as per the suggested guidelines or as per alternatives).
A19: Guideline
A20: a) | B20: Has the user adequately defined and documented design goals for implementing environment separation?
A21: Overall design goals for implementing environment separation | B21: <Observations & response justification - address all subordinate implementation details as documented in the CSCF>
B22: Has the user employed an alternative implementation approach?
B23: <Alternative guideline implementation approach and details>
A24: b) | B24: Has the user adequately defined and implemented the scope for the secure zone?
A25: Scope of the secure zone | B25: <Observations & response justification - address all subordinate implementation details as documented in the CSCF>
B26: Has the user employed an alternative implementation approach?
B27: <Alternative guideline implementation approach and details>
A28: c) | B28: Has the user adequately implemented boundary protections for the secure zone?
A29: Protection of the secure zone - Boundary protection | B29: <Observations & response justification - address all subordinate implementation details as documented in the CSCF>
B30: Has the user employed an alternative implementation approach?
B31: <Alternative guideline implementation approach and details>
A32: d.1) | B32: Has the user adequately controlled local operator (end user and administrator) access to the secure zone?
A33: Access to the secure zone systems - Local operator access | B33: <Observations & response justification - address all subordinate implementation details as documented in the CSCF>
B34: Has the user employed an alternative implementation approach?
B35: <Alternative guideline implementation approach and details>
A36: d.2) | B36: Has the user adequately controlled remote operator (teleworker, "on-call" staff, remote administrator) access to the secure zone?
A37: Access to the secure zone systems - Remote operator access | B37: <Observations & response justification - address all subordinate implementation details as documented in the CSCF>
B38: Has the user employed an alternative implementation approach?
B39: <Alternative guideline implementation approach and details>
A40: e) | B40: Has the user adequately separated the secure zone from general enterprise IT services? | D40: N/A
...

Sheet 1.2
A1: 1.2 (Advisory for B) | B1: OPERATING SYSTEM PRIVILEGED ACCOUNT CONTROL
A2: CONTROL INFORMATION
A3: CONTROL OBJECTIVE Restrict and control the allocation and usage of administrator-level operating system accounts.
A4: IN-SCOPE COMPONENTS | C4: RISK DRIVERS
A5: Administrator-level accounts defined on the following components: | C5: • Deletion of logs and forensic evidence
A6: • Systems or virtual machines (VMs) hosting a Swift-related component (including interface, GUI, Swift or customer connector, jump server) | C6: • Excess privilege or access
A7: • [Advisory: systems or VMs hosting a customer client connector]
A8: • dedicated operator PCs | C8: • Lack of traceability
A9: • network devices protecting the secure zone | C9: • Unauthorized system changes
A10: • on-premises or remote (that is hosted and/or operated by a third party) virtualisation or cloud platform that hosts Swift-related VM’s | C10: • HSM management misused
A11: • New HSM
A12: • [Advisory: customer client connector]
A13: • [Advisory: bridging servers (such as middleware or file transfer servers other than customer connectors) used for and guardian of the secure data exchange between back-office and Swift-related components]
A14: • [Advisory: General-purpose operator PC]
A15: CONTROL STATEMENT Access to administrator-level operating system accounts is restricted to the maximum extent possible. Usage is controlled, monitored, and only permitted for relevant activities such as software installation and configuration, maintenance, and emergency activities. At all other times, an account with least privilege access is used.
A16: CONTROL CONTEXT Tightly protecting administrator-level accounts within the operating system reduces the opportunity for an attacker to use the privileges of the account as part of an attack (for example, executing commands, deleting evidence).
A17: ASSESSMENT RESULTS
A18: Implementation Guideline-Level Detail
A19: Assessors should use a risk based approach to assess the user’s compliance with the CSP control; i.e. assess the security goal, regardless of the implementation method used (be it the suggested guidelines or alternatives). As such, to comply with a CSP security control, users must implement a solution that: (i)Meets the stated control objective, (ii) Addresses the risks and (iii) Covers the documented in-scope components relevant for the user’s architecture. The control statement is a suggested mean to fulfil the control objective and the implementation guidelines are common methods for implementing the control. Even if guidelines can be a good way to start an assessment, the implementation guidance section should never be considered as an "audit checklist" as each user’s implementation may vary. Therefore, in the case that some implementation guidelines elements are not present or partially covered, mitigations as well as particular environment specificities have to be taken into account to properly assess the overall compliance adherence level (again, as per the suggested guidelines or as per alternatives).
A20: Guideline | B20: Has the user adequately restricted and controlled the allocation and usage of administrator-level operating system accounts? | D20: Yes
B21: <Observations & response justification - address all subordinate implementation details as documented in the CSCF> ABCUK's IT admin level operating system accounts are restricted through Server Manager (refer to evidence Swift Admin tab in evidence 1 and 3. Swift SFTP Connector) Active Directory. NPS Security Group properties and network policy server setting were defined through RADIUS client and server. Management confirmed that "root" account is only used in circumstances where sudo or other privileged accounts cannot be used and followed a break-glass procedure. All activities performed using admin accounts are logged through a central logging and monitoring tool, refer to control 6.4 for further details. Access to admin passwords required a change ticket that was requested and approved by two different users (refer to evidence CH-468 IT Hlpdesk - Change Request.pdf).
B22: Has the user employed an alternative implementation approach? | D22: No
B23: <Alternative guideline implementation approach and details>
A24: Summary
A25: Overall Control Disposition | D25: =IF('User Data'!B4="B","Not Applicable",IF(D20="","TBD",IF(OR(D20="Yes",D20="N/A"),"In Place","Not in Place"))) -> In Place
A26: Recommendations
A27: <Recommendations for security enhancements / improvements>

Sheet 1.3
A1: 1.3 (Advisory for B) | B1: VIRTUALISATION OR CLOUD PLATFORM PROTECTION
A2: CONTROL INFORMATION
A3: CONTROL OBJECTIVE Secure the virtualisation or cloud platform and virtual machines (VMs) that host Swift-related components to the same level as physical systems
A4: IN-SCOPE COMPONENTS | C4: RISK DRIVERS
A5: On-premises or remote (that is hosted or operated by a third party, such a a cloud provider, or both) virtualisation or cloud platform and VM's used to host any of the below Swift related components: | C5: • Unauthorised access
A6: • Messaging interface | C6: • Uncontrolled proliferation of systems and data
A7: • Communication interface
A8: • GUI
A9: • SwiftNet Link
A10: • Swift and Customer connector
A11: • [Advisory: customer client connector]
A12: • Jump Server
A13: • Dedicated and general-purpose operator PCs (when using virtual desktops)
A14: • Firewalls
A15: • [Advisory: bridging servers (such as middleware or file transfer servers other than customer connectors) used for and guardian of the secure data exchange between back-office and Swift-related components]
A16: • Alliance Connect Virtual VPN instance
A17: Note: This requirement is not applicable when there is no on-premises and remote virtualisation or cloud platform and no VMs used to host the referred in-scope components. Note: It is reminded that containerised applications have to be considered as co-hosted on the same system that hosts the container itself.
A18: CONTROL STATEMENT Secure virtualisation or cloud platform, virtualised machines and supporting virtual infrastructure (such as e.g. firewalls) to the same level as physical systems.
... A22: Assessors should use a risk based approach to assess the user’s compliance with the CSP control; i.e. assess the security goal, regardless of the implementation method used (be it the suggested guidelines or alternatives). As such, to comply with a CSP security control, users must implement a solution that: (i)Meets the stated control objective, (ii) Addresses the risks and (iii) Covers the documented in-scope components relevant for the user’s architecture. The control statement is a suggested mean to fulfil the control objective and the implementation guidelines are common methods for implementing the control. Even if guidelines can be a good way to start an assessment, the implementation guidance section should never be considered as an "audit checklist" as each user’s implementation may vary. Therefore, in the case that some implementation guidelines elements are not present or partially covered, mitigations as well as particular environment specificities have to be taken into account to properly assess the overall compliance adherence level (again, as per the suggested guidelines or as per alternatives).
A23: Guideline | B23: Has the user adequately secured virtualisation platforms and virtual machines (VM’s) hosting Swift related components to the same level as physical systems? | D23: Yes
B24: <Observations & response justification - address all subordinate implementation details as documented in the CSCF> Architecture diagram (evidence ABCUK - Network Diagram v2.3) was reviewed and it was noted that a segregated environment is implemented for the server hosting SFTP connection that connects to Service Bureau (Service Bureau). ABCUK's Swift in-scope virtual servers are managed using vShphere Client (refer to evidence tab 1.3 of Screenshot 1.3 1.4 1.5 4.2.xls) and are integrated with Active Directory for password policy enforcement. VM are protected through switches and firewalls (SONICWWALL). The evidence also demonstrated that ABC bank has implemented Multi-Factor authencation for accessing Citirx Workspace environment. VMware ESXi servers are managed by third party as Infrastructure as a Software (IaaS). Pentest report evidence Penetration_Test_ABC Bank (UK) Limited_Internal Infrastructure_2024-11-21.pdf was reviewed and it was noted that vulnerabilities against VMware ESXi 7.0 / 8.0 were identified. Evidence Vulnerabilities Tracking 2024.xlsx demonstrates that Critical and High vulnerabilities were tracked and resolved. Vulnerability management and patch management tools are deployed for monitoring and continous scanning of the ABCUK estate. Logging and monitoring of Swift in-scope infrastructure is configured to send alerts to Centrify, a group level tool.
B25: Has the user employed an alternative implementation approach? | D25: No
B26: <Alternative guideline implementation approach and details>
A27: Summary
A28: Overall Control Disposition | D28: =IF('User Data'!B4="B","Not Applicable",IF(D23="","TBD",IF(OR(D23="Yes",D23="N/A"),"In Place","Not in Place"))) -> In Place
A29: Recommendations
A30: <Recommendations for security enhancements / improvements>

Sheet 1.4
A1: 1.4 | B1: RESTRICTION OF INTERNET ACCESS
A2: CONTROL INFORMATION
A3: CONTROL OBJECTIVE Control/Protect Internet access from operator PCs and systems within the secure zone
A4: IN-SCOPE COMPONENTS | C4: RISK DRIVERS
A5: • Dedicated and general-purpose operator PCs | C5: • Exposure to internet-based attacks
A6: • Jump Server
A7: • Messaging interface
A8: • Communication interface
A9: • GUI
A10: • SwiftNet Link
A11: • Swift and customer connector
A12: • [Advisory: customer client connector]
A13: • New HSM
A14: • [Advisory: bridging servers (such as middleware or file transfer servers other than customer connectors) used for and guardian of the secure data exchange between back-office and Swift-related components]
A15: • [Advisory: on-premises or remote (that is hosted and/or operated by a third party) virtualisation or cloud platform and their management PCs]
A16: CONTROL STATEMENT All general-purpose and dedicated operator PCs as well as systems within the secure zone have controlled direct internet access in line with business
A17: CONTROL CONTEXT Direct access to the Internet raises exposure to internet-based attacks. Risk is even higher in case of human interactions (browsing, e-mails, or other social network activities being permitted). Once compromised, those systems can be an entry point that allows lateral movements or injection of command and control elements (or a combination of both). If reducing the attack surface and vulnerabilities of those systems (as per the relevant controls identified in this document) is primordial, then limiting and controlling direct Internet accesses is crucial. On top of (general) operator PCs that connect Swift-related services or applications offered by outsourcing agents,Swift (in the case of Alliance Lite2 or Alliance Cloud) or Swift connectivity providers, due diligence must be taken to secure (general) operator PCs used to access on-premises interfaces or GUIs. Insecurely combining access to the “production environment” and the Internet could be abused by attackers.
... A20: Assessors should use a risk based approach to assess the user’s compliance with the CSP control; i.e. assess the security goal, regardless of the implementation method used (be it the suggested guidelines or alternatives). As such, to comply with a CSP security control, users must implement a solution that: (i)Meets the stated control objective, (ii) Addresses the risks and (iii) Covers the documented in-scope components relevant for the user’s architecture. The control statement is a suggested mean to fulfil the control objective and the implementation guidelines are common methods for implementing the control. Even if guidelines can be a good way to start an assessment, the implementation guidance section should never be considered as an "audit checklist" as each user’s implementation may vary. Therefore, in the case that some implementation guidelines elements are not present or partially covered, mitigations as well as particular environment specificities have to be taken into account to properly assess the overall compliance adherence level (again, as per the suggested guidelines or as per alternatives).
A21: Guideline | B21: Has the user adequately restricted internet access from the secure zone and from general-purpose operator PCs (and from other components like middleware servers or the virtualisation platform - Advisory) in line with the business needs? | D21: Yes
B22: <Observations & response justification - address all subordinate implementation details as documented in the CSCF> Internet access is restricted on servers hosting SFTP connection to service bureau for Swift connectivity. Screenshot evidence (refer to tab 1.4, Screenshot 1.3, 1.4, 1.5, 4.2) demonstrated that internet access cannot be established to google.com from ABCUKDC2-AR01 server and all packets were lost showing 100% loss. Internet access is controlled on the general operator PCs which is achieved through whitelisted IP/ URL destination using proxy content inspection. Barracuda proxy is used to impelent whitelisting and blacklisting using TLS 1.3 and AES_128_GCM encryption is in use for accessing the interfaces.
B23: Has the user employed an alternative implementation approach? | D23: No
B24: <Alternative guideline implementation approach and details>
A25: Summary
A26: Overall Control Disposition | D26: =IF(D21="","TBD",IF(OR(D21="Yes",D21="N/A"),"In Place","Not in Place")) -> In Place
A27: Recommendations
A28: <Recommendations for security enhancements / improvements>

Sheet 1.5
A1: 1.5 | B1: CUSTOMER ENVIRONMENT PROTECTION
A2: CONTROL INFORMATION
A3: CONTROL OBJECTIVE Ensure the protection of the customer’s connectivity infrastructure from external environment and potentially compromised elements of the general IT environment.
A4: IN-SCOPE COMPONENTS | C4: RISK DRIVERS
A5: • Customer connector | C5: • Compromise of enterprise authentication system
A6: • Dedicated and general-purpose operator PCs | C6: • Compromise of user credentials
A7: • Jump server | C7: • Credential replay
A8: • HSM when used with customer connector | C8: • Exposure to internet-based attacks
A9: • [Advisory: customer client connector] | C9: • Unauthorized access
A10: CONTROL STATEMENT A separated secure zone safeguards the customer's infrastructure used for external connectivity from external environments and compromises or attacks on the broader enterprise environment.
A11: CONTROL CONTEXT Segmentation between the customer's connectivity infrastructure and its larger enterprise network reduces the attack surface and has shown to be an effective way to defend against cyber attacks that commonly involve compromise of the general enterprise IT environment. Effective segmentation will include network-level separation, access restrictions, and connectivity restrictions.
A12: ASSESSMENT RESULTS
A13: Implementation Guideline-Level Detail
A14: Assessors should use a risk based approach to assess the user’s compliance with the CSP control; i.e. assess the security goal, regardless of the implementation method used (be it the suggested guidelines or alternatives). As such, to comply with a CSP security control, users must implement a solution that: (i)Meets the stated control objective, (ii) Addresses the risks and (iii) Covers the documented in-scope components relevant for the user’s architecture. The control statement is a suggested mean to fulfil the control objective and the implementation guidelines are common methods for implementing the control. Even if guidelines can be a good way to start an assessment, the implementation guidance section should never be considered as an "audit checklist" as each user’s implementation may vary. Therefore, in the case that some implementation guidelines elements are not present or partially covered, mitigations as well as particular environment specificities have to be taken into account to properly assess the overall compliance adherence level (again, as per the suggested guidelines or as per alternatives).
A15: Guideline
A16: a) | B16: Has the user adequately defined and documented design goals for implementing environment separation? | D16: Yes
A17: Overall design goals for implementing environment separation | B17: <Observations & response justification - address all subordinate implementation details as documented in the CSCF> A Network Configuration Policy is defined by ABCUK's which was last reviewed in August 2025. The policy states that "Networks will be segregated to prevent access overlap and to minimise the impact of any threat to the network". Through inspection of the network diagram it was noted that the Windows server used for hosting SFTP connection that processes traffic to the service bureau is isolated through network level segregation. Architecture diagram (evidence ABCUK - Network Diagram v2.3) was reviewed which demonstrated that a segregated environment is implemented for the server hosting SFTP connection that connects to Service Bureau (Service Bureau). Dedicated firewalls provide logical seperation for the Swift secrue zone so that there is no leak from one Active Directory to another. Environment is further separeated through Access Controls List, application firewalls, network swtiches and encryption.
B18: Has the user employed an alternative implementation approach? | D18: No
B19: <Alternative guideline implementation approach and details>
A20: b) | B20: Has the user adequately defined and implemented the scope for the secure zone? | D20: Yes
A21: Scope of the secure zone | B21: <Observations & response justification - address all subordinate implementation details as documented in the CSCF> Swift in-scope components are hosted on a specific server and the zone is secured through segregation using dedicated firewalls to create a logical separation.
B22: Has the user employed an alternative implementation approach? | D22: No
B23: <Alternative guideline implementation approach and details>
A24: c) | B24: Has the user adequately implemented boundary protections for the secure zone? | D24: Yes
A25: Protection of the secure zone - Boundary protection | B25: <Observations & response justification - address all subordinate implementation details as documented in the CSCF> Network level diagram demonstrates network level segregation and presence of firewalls for boundary proectection. Firewalls are configured for protection of the Swift in-scope components. Firewalls rules are setup with "deny all" principle. Firewalls are reviewed on monthly basis and all connections via firewalls are logged and monitored. A firewall review was conducted by an external third party, LRQA, (refer to evidence Firewall Reviews - Technical Report - 05 Nov 2024), the report concluded that there were 0 Critical, 3 high findings that were subsequently remediated.
B26: Has the user employed an alternative implementation approach? | D26: No
B27: <Alternative guideline implementation approach and details>
A28: d.1) | B28: Has the user adequately controlled local operator (end user and administrator) access to the secure zone? | D28: Yes
A29: Access to the secure zone systems - Local operator (end user and administrator) access | B29: <Observations & response justification - address all subordinate implementation details as documented in the CSCF> Access to the secure-zone is restricted to specified administrators further this is controlled through Active Directory that is defined based on Seperation of Duty, need to know and least provilege principle.
B30: Has the user employed an alternative implementation approach? | D30: No
B31: <Alternative guideline implementation approach and details>
A32: d.2) | B32: Has the user adequately controlled remote operator (teleworker, "on-call" staff, remote administrator) access to the secure zone? | D32: Yes
A33: Access to the secure zone systems - Remote operator access | B33: <Observations & response justification - address all subordinate implementation details as documented in the CSCF> Access to the secure-zone using remote access is controlled through VPN encryption.
B34: Has the user employed an alternative implementation approach? | D34: No
B35: <Alternative guideline implementation approach and details>
A36: e) | B36: Has the user adequately separated the secure zone from general enterprise IT services? | D36: Yes
A37: Separation from general enterprise IT services | B37: <Observations & response justification - address all subordinate implementation details as documented in the CSCF> Separation from general enterprise IT services is achieved by hosting Swift in-scope component (SFTP) on dedicated server that is further separated using Active Directory, firewalls and network switches.
B38: Has the user employed an alternative implementation approach? | D38: No
B39: <Alternative guideline implementation approach and details>
A40: Summary
...

Sheet 2.1
A1: 2.1 | B1: INTERNAL DATA FLOW SECURITY
A2: CONTROL INFORMATION
A3: CONTROL OBJECTIVE Ensure the confidentiality, integrity, and authenticity of application data flows between user's Swift-related Components.
A4: IN-SCOPE COMPONENTS | C4: RISK DRIVERS
C5: • Loss of sensitive data confidentiality
A6: • On-premises or remote (hosted and/or operated by a third party, or both) user's Swift infrastructure and related components (including new HSM) | C6: • Loss of sensitive data integrity
C7: • Unauthenticated system traffic
C8: • Unauthorised access
A10: CONTROL STATEMENT Confidentiality, integrity, and authentication mechanisms are implemented to protect Swift-related component-to-component or system-to-system data flows.
A11: CONTROL CONTEXT The protection of internal data flows safeguards against unintended disclosure, modification, and access of the data while in transit
A12: ASSESSMENT RESULTS
A13: Implementation Guideline-Level Detail
A14: Assessors should use a risk based approach to assess the user’s compliance with the CSP control; i.e. assess the security goal, regardless of the implementation method used (be it the suggested guidelines or alternatives). As such, to comply with a CSP security control, users must implement a solution that: (i)Meets the stated control objective, (ii) Addresses the risks and (iii) Covers the documented in-scope components relevant for the user’s architecture. The control statement is a suggested mean to fulfil the control objective and the implementation guidelines are common methods for implementing the control. Even if guidelines can be a good way to start an assessment, the implementation guidance section should never be considered as an "audit checklist" as each user’s implementation may vary. Therefore, in the case that some implementation guidelines elements are not present or partially covered, mitigations as well as particular environment specificities have to be taken into account to properly assess the overall compliance adherence level (again, as per the suggested guidelines or as per alternatives).
A15: Guideline | B15: Has the user ensured the confidentiality, integrity, and authenticity of data flows between local Swift-related applications ?
B16: <Observations & response justification - address all subordinate implementation details as documented in the CSCF>
B17: Has the user employed an alternative implementation approach?
B18: <Alternative guideline implementation approach and details>
A19: Summary
A20: Overall Control Disposition | D20: =IF(OR('User Data'!B4="B",'User Data'!B4="A4"),"Not Applicable",IF(D15="","TBD",IF(OR(D15="Yes",D15="N/A"),"In Place","Not in Place"))) -> Not Applicable
A21: Recommendations
A22: <Recommendations for security enhancements / improvements>

Sheet 2.2
A1: 2.2 | B1: SECURITY UPDATES
A2: CONTROL INFORMATION
A3: CONTROL OBJECTIVE Minimize the occurrence of known technical vulnerabilities on operator PCs and within the user's Swift infrastructure by ensuring vendor support, applying mandatory software updates, and applying timely security updates aligned to the assessed risk.
A4: IN-SCOPE COMPONENTS | C4: RISK DRIVERS
A5: Hardware and all software running on the following systems, virtual machine, hosts, servers or devices: | C5: • Exploitation of known security vulnerabilities
A6: • physical systems or virtual machines (VMs) hosting a Swift-related component (including interface, GUI, Swift or customer connector)
A7: [Advisory: customer client connector]
A8: • Dedicated and general-purpose operator PC
A9: • jump server
A10: • On-premises or remote (that is hosted and/or operated by a third party) virtualisation or cloud platform hosting Swift-related VM’s and their management PCs
A11: • network devices protecting the secure zone
A12: • New HSM
A13: • [Advisory: bridging servers (such as middleware or file transfer servers other than customer connectors) used for and guardian of the secure data exchange between back-office and Swift-related components]
A14: CONTROL STATEMENT All hardware and software inside the secure zone and on operator PCs are within the support lifecycle of the vendor, have been upgraded with mandatory software updates, and have had security updates promptly applied.
A15: CONTROL CONTEXT The closure of known security vulnerabilities is effective in reducing the various pathways that an attacker may use during an attack. A security update process that is comprehensive, repeatable and implemented in a timely manner, is necessary to continuously close these known vulnerabilities when security patches are available.
A16: ASSESSMENT RESULTS
A17: Implementation Guideline-Level Detail
A18: Assessors should use a risk based approach to assess the user’s compliance with the CSP control; i.e. assess the security goal, regardless of the implementation method used (be it the suggested guidelines or alternatives). As such, to comply with a CSP security control, users must implement a solution that: (i)Meets the stated control objective, (ii) Addresses the risks and (iii) Covers the documented in-scope components relevant for the user’s architecture. The control statement is a suggested mean to fulfil the control objective and the implementation guidelines are common methods for implementing the control. Even if guidelines can be a good way to start an assessment, the implementation guidance section should never be considered as an "audit checklist" as each user’s implementation may vary. Therefore, in the case that some implementation guidelines elements are not present or partially covered, mitigations as well as particular environment specificities have to be taken into account to properly assess the overall compliance adherence level (again, as per the suggested guidelines or as per alternatives).
A19: Guideline | B19: Has the user minimized the occurrence of known technical vulnerabilities within the local Swift infrastructure by ensuring vendor support, applying mandatory software updates, and applying timely security updates aligned to the assessed risk? | D19: Yes
B20: <Observations & response justification - address all subordinate implementation details as documented in the CSCF> ABCUK has defined Vulnerability Management Policy, Standard and Procedure (evidence ABCUK-POL-ALL-014, ABCUK, STD-ALL-033 and ABCUK-PRC-ALL-015). The Policy was last reviewed in August 2025. Through inspection of evidence provided (refer to evidence 1 and 3 Swift SFTP Connection) it was noted that Swift connection is established through VMware Platform and Cirix servers were used for ABCUK users for remote connectivity. These connections were established through Microsoft Windows Server 2022 (64-bit) servers that are vendor supported till 2026. It was further noted that asset list registered (evidence ABCUK Assets Review 25Q3) was maintained by the organisation and operator laptops and desktop were on vendor supported versions.
B21: Has the user employed an alternative implementation approach? | D21: No
B22: <Alternative guideline implementation approach and details>
A23: Summary
A24: Overall Control Disposition | D24: =IF(D19="","TBD",IF(OR(D19="Yes",D19="N/A"),"In Place","Not in Place")) -> In Place
A25: Recommendations
A26: <Recommendations for security enhancements / improvements>

Sheet 2.3
A1: 2.3 | B1: SYSTEM HARDENING
A2: CONTROL INFORMATION
A3: CONTROL OBJECTIVE Reduce the cyber attack surface of Swift-related components by performing system hardening.
A4: IN-SCOPE COMPONENTS | C4: RISK DRIVERS
A5: • dedicated and general-purpose operator PC | C5: • Excess attack surface
A6: • jump server | C6: • Exploitation of insecure system configuration
A7: • Systems (physical or VMs) hosting a Swift-related component (including interface, GUI, Swift or customer connector)
A8: • [Advisory: customer client connector]
A9: • On-premises or remote (that is hosted and/or operated by a third party) virtualisation or cloud platform (also referred as the hypervisor) hosting Swift-related VM’s and their management PCs
A10: • network devices protecting the secure zone
A11: • [Advisory: bridging servers (such as middleware servers other than customer connectors) used for data exchange between back-office and Swift-related components]
A12: CONTROL STATEMENT Security hardening is conducted on all in-scope components.
A13: CONTROL CONTEXT System hardening applies the security concept of “least privilege” to a system by disabling features and services that are not required for normal system operations. This process reduces the system capabilities, features, and protocols that a malicious person may use during an attack.
A14: ASSESSMENT RESULTS
A15: Implementation Guideline-Level Detail
A16: Assessors should use a risk based approach to assess the user’s compliance with the CSP control; i.e. assess the security goal, regardless of the implementation method used (be it the suggested guidelines or alternatives). As such, to comply with a CSP security control, users must implement a solution that: (i)Meets the stated control objective, (ii) Addresses the risks and (iii) Covers the documented in-scope components relevant for the user’s architecture. The control statement is a suggested mean to fulfil the control objective and the implementation guidelines are common methods for implementing the control. Even if guidelines can be a good way to start an assessment, the implementation guidance section should never be considered as an "audit checklist" as each user’s implementation may vary. Therefore, in the case that some implementation guidelines elements are not present or partially covered, mitigations as well as particular environment specificities have to be taken into account to properly assess the overall compliance adherence level (again, as per the suggested guidelines or as per alternatives).
A17: Guideline | B17: Has the user reduced the cyber attack surface of Swift-related components by performing system hardening? | D17: Yes
B18: <Observations & response justification - address all subordinate implementation details as documented in the CSCF> ABCUK has a defined policy for System Configuration (refer to evidence System Configuration & Maintenance Policy) that was last reviewed in August 2025. This policy states that a configuration baseline to be created for all systems implemented and to be stored in a configuration management repositary or equivalent and that it adheres to industry best practices such as: removal of vendor defaults and default accounts, encryption requirement for addmin access and updating configuration standards based on Vulnerability management procedure etc. . The ISO 27001 certification (evidence Audit Summary Report _The Audit.pdf) was reviewed, it was noted that it demonstrates that Security standards are observed and there were 0 (Zero)/ no major findings. System hardening is held in conjunction with Vulnerability Management, where operating systems are scanned and flaws identified. The output of scans are sent to the system hardening process for optimisation of configuration management. GPOs are used to push updates and configuration changes to OS as and when required. Disabling USB device ports, updating whitelisting and blacklisting policies, screen lockouts amongst others were provided as evidence for this assessment. Active Directory security review was conducted by a third party LRQA ABC Bank (UK) Limited - Active Directory Security Review - October 2024 and it was noted that vulnerabilities identified were resolved as per evidence vulnerability tracking (evidence Vulnerability Tracking 2024.xlsx).
B19: Has the user employed an alternative implementation approach? | D19: No
B20: <Alternative guideline implementation approach and details>
A21: Summary
A22: Overall Control Disposition | D22: =IF(D17="","TBD",IF(OR(D17="Yes",D17="N/A"),"In Place","Not in Place")) -> In Place
A23: Recommendations
A24: <Recommendations for security enhancements / improvements>

Sheet 2.6
A1: 2.6 | B1: OPERATOR SESSION CONFIDENTIALITY AND INTEGRITY
A2: CONTROL INFORMATION
A3: CONTROL OBJECTIVE Protect the confidentiality and integrity of interactive operator sessions that connect to the on-premises or remote (operated by a service provider) Swift infrastructure or to a service provider Swift-related applications.
A4: IN-SCOPE COMPONENTS | C4: RISK DRIVERS
A5: Interactive user, operator or management sessions performed from:
A6: • Dedicated and general-purpose operator PC | C6: • Loss of operational confidentiality
A7: • jump server | C7: • Loss of operational integrity
A8: • Any another intermediate system accessed or used from any of the above to connect to | C8: • Password theft
A9: • Jump server or any other intermediate system accessed or used from any of the above
A10: • systems hosting a Swift-related component (including interface, GUI, Swift and customer connectors)
A11: • network devices protecting the secure zone
A12: • management console of a virtualisation or cloud platform hosting Swift-related components (including Swift and customer connector)
A13: • interface applications, GUI and Swift or customer connector in the secure zone
A14: • [Advisory: customer client connector]
A15: • Swift-related applications at the service provider
A16: • HSM
A17: • [Advisory: bridging servers (such as middleware servers other than customer connectors) used for and guardian of the secure data exchange between back-office and Swift-related components]
A18: CONTROL STATEMENT The confidentiality and integrity of interactive operator sessions that connect to service provider Swift-related applications or into the user's secure zone is safeguarded.
A19: CONTROL CONTEXT Operator sessions, through the jump server when accessing the on-premises or remote (that is hosted or operated by a third party, or both) Swift infrastructure, pose a unique threat because unusual or unexpected activity is more difficult to detect during interactive sessions than it is during application-to-application activity. Therefore, it is important to protect the integrity and confidentiality of these operator sessions to reduce any opportunity for misuse or password theft. When used, access to the virtualisation layer (virtualisation or cloud management console) must be similarly protected.
A20: ASSESSMENT RESULTS
... A22: Assessors should use a risk based approach to assess the user’s compliance with the CSP control; i.e. assess the security goal, regardless of the implementation method used (be it the suggested guidelines or alternatives). As such, to comply with a CSP security control, users must implement a solution that: (i)Meets the stated control objective, (ii) Addresses the risks and (iii) Covers the documented in-scope components relevant for the user’s architecture. The control statement is a suggested mean to fulfil the control objective and the implementation guidelines are common methods for implementing the control. Even if guidelines can be a good way to start an assessment, the implementation guidance section should never be considered as an "audit checklist" as each user’s implementation may vary. Therefore, in the case that some implementation guidelines elements are not present or partially covered, mitigations as well as particular environment specificities have to be taken into account to properly assess the overall compliance adherence level (again, as per the suggested guidelines or as per alternatives).
A23: Guideline | B23: Has the user adequately protected the confidentiality and integrity of interactive operator sessions connecting to the local Swift infrastructure? | D23: Yes
B24: <Observations & response justification - address all subordinate implementation details as documented in the CSCF> ABCUK has defined an Access Control Policy that approved in August 2025, which states that data is required to be protected from unauthorised access to computer, application and operating systems through authentication standards (ABCUK-STD-ALL-008). It was noted that encryption for securing data in motion using TLS 1.3, AES_128_GCM. The traffic between ABCUK and Service Bureau is encrypted and using SSH protocol is used to connect to servers and for integrity verification SHA-384 is used. SWIFT Operators use GUI to access the messaging interface provided by the service bureau. There is no provision of keying in payments directly through the interface these can only be verified and authorised via the GUI. In-activity timeout is lock the screen is configured on ABCUK's devices including in-scope Opeartor PC. The operators are required to enter their credentials to log back into the system GUI timeout is set to 300 seconds.
B25: Has the user employed an alternative implementation approach? | D25: No
B26: <Alternative guideline implementation approach and details>
A27: Summary
A28: Overall Control Disposition | D28: =IF(D23="","TBD",IF(OR(D23="Yes",D23="N/A"),"In Place","Not in Place")) -> In Place
A29: Recommendations
A30: <Recommendations for security enhancements / improvements>

Sheet 2.7
A1: 2.7 (Advisory for B) | B1: VULNERABILITY SCANNING
A2: CONTROL INFORMATION
A3: CONTROL OBJECTIVE Identify known vulnerabilities within the user's Swift environment by implementing a regular vulnerability scanning process and act upon results.
A4: IN-SCOPE COMPONENTS | C4: RISK DRIVERS
A5: • Jump server | C5: • Exploitation of known security vulnerabilities
A6: • Dedicated operator PC | C6: • Unknown security vulnerabilities or security misconfigurations
A7: • all systems hosting a Swift-related component (including interface, GUI, Swift and customer connectors),
A8: • [Advisory: systems hosting a customer client connector]
A9: • [Advisory: on-premises or remote (that is hosted and/or operated by a third party) virtualisation or cloud platform hosting Swift-related VM’s and their management PCs as per optional enhancement]
A10: • [Advisory: bridging servers (such as middleware or file transfer servers other than customer connector used for data exchange between back-office and Swift-related components]
A11: • [Advisory: general-purpose operator PCs as per the optional enhancement]
A12: CONTROL STATEMENT Secure zone (including dedicated operator PC) systems are scanned for vulnerabilities at OS and application level using an up-to-date, reputable scanning tool and results, reported by the tool, are considered for appropriate resolving actions.
